Lmod has detected the following error: The following module(s) are unknown:
"cuda11.8/toolkit/11.8.0"

Please check the spelling or version number. Also try "module spider ..."
It is also possible your cache file is out-of-date; it may help to try:
  $ module --ignore-cache load "cuda11.8/toolkit/11.8.0"

Also make sure that all modulefiles written in TCL start with the string
#%Module



	To use after loading the module, enter the following:
	    eval "$(/risapps/rhel7/miniconda3/38_4.9.2/bin/conda shell.bash hook)"
2024-03-03 10:38:36 - CRITICAL: MODEL PARAMETERS
2024-03-03 10:38:36 - INFO: dataset_path = data/dataset/graphed.csv
2024-03-03 10:38:36 - INFO: train_validation_test_split = [0.75, 0.0, 0.25]
2024-03-03 10:38:36 - INFO: batch_size = 8
2024-03-03 10:38:36 - INFO: num_workers = 8
2024-03-03 10:38:36 - INFO: hidden_channels = 64
2024-03-03 10:38:36 - INFO: epochs = 2
2024-03-03 10:38:36 - INFO: learning_rate = 1e-05
2024-03-03 10:38:36 - CRITICAL: MODEL PROPERTIES
2024-03-03 10:38:36 - INFO: num_train = 1601
2024-03-03 10:38:36 - INFO: num_validation = 0
2024-03-03 10:38:36 - INFO: num_test = 533
2024-03-03 10:38:36 - INFO: example_graph = Data(x=[3059, 39], edge_index=[2, 449978], edge_attr=[449978, 2], y=[3059], pos=[3059, 3], sasa=[3059], surface_accessible=[3059], num_nodes=3059, num_node_features=39, num_edges=449978, num_edge_features=2, num_dimensions=3, graph_path='data/dataset/6KJD_A/graph.pyg', protein_path='data/dataset/6KJD_A/protein.pdb', labels_path='data/dataset/6KJD_A/labels.npy', radius_ncov=10)
2024-03-03 10:38:43 - CRITICAL: MODEL ARCHITECTURE
2024-03-03 10:38:43 - INFO: device = cuda
2024-03-03 10:38:43 - INFO: model = GCN(
  (conv1): GATv2Conv(39, 64, heads=1)
  (conv2): GATv2Conv(64, 64, heads=1)
  (conv3): GATv2Conv(64, 1, heads=1)
)
2024-03-03 10:38:43 - INFO: optimizer = Adam (
Parameter Group 0
    amsgrad: False
    betas: (0.9, 0.999)
    capturable: False
    differentiable: False
    eps: 1e-08
    foreach: None
    fused: None
    lr: 1e-05
    maximize: False
    weight_decay: 0.0001
)
2024-03-03 10:38:43 - INFO: criterion = BCEWithLogitsLoss()
2024-03-03 10:38:43 - CRITICAL: MODEL TRAINING
2024-03-03 10:39:22 - INFO: epoch 000: epoch_loss = 0.7281, mu_ncov = 9.9979
2024-03-03 10:39:53 - INFO: epoch 001: epoch_loss = 0.6711, mu_ncov = 9.9958
2024-03-03 10:39:53 - CRITICAL: MODEL TESTING
2024-03-03 10:40:05 - INFO: true positive: 0
2024-03-03 10:40:05 - INFO: true negative: 787455
2024-03-03 10:40:05 - INFO: false positive: 0
2024-03-03 10:40:05 - INFO: false negative: 14043
2024-03-03 10:40:05 - INFO: recall = 0.0
Traceback (most recent call last):
  File "/rsrch4/home/genomic_med/rcheeter/druggabilityclassifier/model.py", line 243, in <module>
    main()
  File "/rsrch4/home/genomic_med/rcheeter/druggabilityclassifier/model.py", line 236, in main
    logger.info(f"mu_cov = {model.mu_cov.data.numpy()[0]:.4f}")
                            ^^^^^^^^^^^^^^^^^^^^^^^^^
TypeError: can't convert cuda:0 device type tensor to numpy. Use Tensor.cpu() to copy the tensor to host memory first.
